<robot name="arm">

  <link name="base_link">
    <visual>
      <origin xyz="0 0 0.005" rpy="0 0 0"/>
      <geometry>
        <cylinder length="0.01" radius="0.1"/>
      </geometry>
      <material name="yellow">
        <color rgba="1 0.4 0 1"/>
      </material>
    </visual>
  </link>
  <link name="arm_link1">
    <visual>
      <origin xyz="0 0 0" rpy="0 0 0"/>
      <geometry>
        <cylinder length="0.02" radius="0.01"/>
      </geometry>
      <material name="gray">
        <color rgba="0.75 0.75 0.75 1"/>
      </material>
    </visual>
  </link>
  <link name="arm_link2">
    <visual>
      <origin xyz="0 0 0" rpy="0 0 0"/>
      <geometry>
        <cylinder length="0.02" radius="0.01"/>
      </geometry>
      <material name="gray">
        <color rgba="0.75 0.75 0.75 1"/>
      </material>
    </visual>
  </link>

  <joint name="joint1" type="continuous">
    <parent link="base_link"/>
    <child link="arm_link1"/>
    <origin xyz="0 0 0.02" rpy="0 0 0" />
    <axis xyz="0 0 1" />
  </joint>
  <joint name="joint2" type="continuous">
    <parent link="arm_link1"/>
    <child link="arm_link2"/>
    <origin xyz="0.02 0 0" rpy="0 1.5857963 0" />
    <axis xyz="0 0 1" />
  </joint>

</robot>
