<?xml version="1.0" ?>
<!-- =================================================================================== -->
<!-- |    This document waarm_gazebos autogenerated by xacro from /home/kaixinguo/work/helloros/src/learning_description/urdf/arm_description.urdf.xacro | -->
<!-- |    EDITING THIS FILE BY HAND IS NOT RECOMMENDED                                 | -->
<!-- =================================================================================== -->
<robot name="arm_robot" xmlns:xacro="http://www.ros.org/wiki/xacro">
    <gazebo>
        <plugin filename="libgazebo_ros_control.so" name="ros_control">
            <robotNamespace>/</robotNamespace>
            <legacyModeNS>true</legacyModeNS>
        </plugin>
    </gazebo>
    <gazebo>
        <plugin filename="libgazebo_ros_joint_state_publisher.so" name="joint_state_publisher">
            <jointName>motor_S_joint, motor_L_joint, motor_U_joint, motor_R_joint, motor_B_joint, motor_T_joint</jointName>
            <updateRate>50</updateRate>
            <alwaysOn>true</alwaysOn>
        </plugin>
    </gazebo>
    <link name="base_link" />
    <link name="base">
        <visual>
            <origin rpy="0 0 0" xyz="0 0 0" />
            <geometry>
                <cylinder length="0.02" radius="0.01" />
            </geometry>
            <material name="yellow">
                <color rgba="1 0.4 0 1" />
            </material>
        </visual>
        <collision>
            <geometry>
                <cylinder length="0.02" radius="0.01" />
            </geometry>
        </collision>

        <inertial>
            <origin rpy="0 0 0" xyz="0 0 0" />
            <mass value="1" />
            <inertia ixx="5.833331e-05" ixy="0.0" ixz="0.0" iyy="5.833331e-05" iyz="0.0" izz="5e-05" />
        </inertial>

    </link>
    <joint name="base_joint" type="fixed">
        <parent link="base_link" />
        <child link="base" />
        <origin rpy="0 0 0" xyz="0 0 0.01" />
    </joint>
    <gazebo reference="base">
        <material>Gazebo/Yellow</material>
    </gazebo>
    <link name="motor_S">
        <visual>
            <origin rpy="0 0 0" xyz="0 0 0" />
            <geometry>
                <cylinder length="0.02" radius="0.01" />
            </geometry>
            <material name="gray">
                <color rgba="0.75 0.75 0.75 1" />
            </material>
        </visual>
        <collision>
            <geometry>
                <cylinder length="0.02" radius="0.01" />
            </geometry>
        </collision>

        <inertial>
            <origin rpy="0 0 0" xyz="0 0 0" />
            <mass value="1" />
            <inertia ixx="5.833331e-05" ixy="0.0" ixz="0.0" iyy="5.833331e-05" iyz="0.0" izz="5e-05" />
        </inertial>

    </link>
    <joint name="motor_S_joint" type="continuous">
        <parent link="base" />
        <child link="motor_S" />
        <origin rpy="0 0 0" xyz="0 0 0.02" />
        <axis xyz="0 0 1" />
        <limit effort="150.0" velocity="3.14159265" />
        <dynamics damping="0.0" friction="0.0" />
    </joint>
    <transmission name="motor_S_joint_trans">
        <type>transmission_interface/SimpleTransmission</type>
        <joint name="motor_S_joint">
            <hardwareInterface>hardware_interface/PositionJointInterface</hardwareInterface>
        </joint>
        <actuator name="motor_S_joint_motor">
            <hardwareInterface>hardware_interface/PositionJointInterface</hardwareInterface>
            <mechanicalReduction>1</mechanicalReduction>
        </actuator>
    </transmission>
    <gazebo reference="motor_S">
        <material>Gazebo/Gray</material>
    </gazebo>
    <link name="motor_L">
        <visual>
            <origin rpy="0 0 0" xyz="0 0 0" />
            <geometry>
                <cylinder length="0.02" radius="0.01" />
            </geometry>
            <material name="gray">
                <color rgba="0.75 0.75 0.75 1" />
            </material>
        </visual>
        <collision>
            <geometry>
                <cylinder length="0.02" radius="0.01" />
            </geometry>
        </collision>

        <inertial>
            <origin rpy="0 0 0" xyz="0 0 0" />
            <mass value="1" />
            <inertia ixx="5.833331e-05" ixy="0.0" ixz="0.0" iyy="5.833331e-05" iyz="0.0" izz="5e-05" />
        </inertial>

    </link>
    <joint name="motor_L_joint" type="continuous">
        <parent link="motor_S" />
        <child link="motor_L" />
        <origin rpy="0 1.570796325 0" xyz="0.02 0 0" />
        <axis xyz="0 0 1" />
        <limit effort="150.0" velocity="3.14159265" />
        <dynamics damping="0.0" friction="0.0" />
    </joint>
    <transmission name="motor_L_joint_trans">
        <type>transmission_interface/SimpleTransmission</type>
        <joint name="motor_L_joint">
            <hardwareInterface>hardware_interface/PositionJointInterface</hardwareInterface>
        </joint>
        <actuator name="motor_L_joint_motor">
            <hardwareInterface>hardware_interface/PositionJointInterface</hardwareInterface>
            <mechanicalReduction>1</mechanicalReduction>
        </actuator>
    </transmission>
    <gazebo reference="motor_L">
        <material>Gazebo/Gray</material>
    </gazebo>
    <link name="pole_1">
        <visual>
            <origin rpy="0 0 0" xyz="0 0 0" />
            <geometry>
                <cylinder length="0.1" radius="0.01" />
            </geometry>
            <material name="white">
                <color rgba="1 1 1 1" />
            </material>
        </visual>
        <collision>
            <geometry>
                <cylinder length="0.1" radius="0.01" />
            </geometry>
        </collision>

        <inertial>
            <origin rpy="0 0 0" xyz="0 0 0" />
            <mass value="5" />
            <inertia ixx="0.00429166495" ixy="0.0" ixz="0.0" iyy="0.00429166495" iyz="0.0" izz="0.00025" />
        </inertial>

    </link>
    <joint name="pole_1_joint" type="fixed">
        <parent link="motor_L" />
        <child link="pole_1" />
        <origin rpy="1.570796325 0 0" xyz="0 0.06 0" />
    </joint>
    <gazebo reference="pole_1">
        <material>Gazebo/White</material>
    </gazebo>
    <link name="motor_U">
        <visual>
            <origin rpy="0 0 0" xyz="0 0 0" />
            <geometry>
                <cylinder length="0.02" radius="0.01" />
            </geometry>
            <material name="gray">
                <color rgba="0.75 0.75 0.75 1" />
            </material>
        </visual>
        <collision>
            <geometry>
                <cylinder length="0.02" radius="0.01" />
            </geometry>
        </collision>

        <inertial>
            <origin rpy="0 0 0" xyz="0 0 0" />
            <mass value="1" />
            <inertia ixx="5.833331e-05" ixy="0.0" ixz="0.0" iyy="5.833331e-05" iyz="0.0" izz="5e-05" />
        </inertial>

    </link>
    <joint name="motor_U_joint" type="continuous">
        <parent link="pole_1" />
        <child link="motor_U" />
        <origin rpy="-1.570796325 0 0" xyz="0 0 -0.06" />
        <axis xyz="0 0 1" />
        <limit effort="150.0" velocity="3.14159265" />
        <dynamics damping="0.0" friction="0.0" />
    </joint>
    <transmission name="motor_U_joint_trans">
        <type>transmission_interface/SimpleTransmission</type>
        <joint name="motor_U_joint">
            <hardwareInterface>hardware_interface/PositionJointInterface</hardwareInterface>
        </joint>
        <actuator name="motor_U_joint_motor">
            <hardwareInterface>hardware_interface/PositionJointInterface</hardwareInterface>
            <mechanicalReduction>1</mechanicalReduction>
        </actuator>
    </transmission>
    <gazebo reference="motor_U">
        <material>Gazebo/Gray</material>
    </gazebo>
    <link name="motor_R">
        <visual>
            <origin rpy="0 0 0" xyz="0 0 0" />
            <geometry>
                <cylinder length="0.02" radius="0.01" />
            </geometry>
            <material name="gray">
                <color rgba="0.75 0.75 0.75 1" />
            </material>
        </visual>
        <collision>
            <geometry>
                <cylinder length="0.02" radius="0.01" />
            </geometry>
        </collision>

        <inertial>
            <origin rpy="0 0 0" xyz="0 0 0" />
            <mass value="1" />
            <inertia ixx="5.833331e-05" ixy="0.0" ixz="0.0" iyy="5.833331e-05" iyz="0.0" izz="5e-05" />
        </inertial>

    </link>
    <joint name="motor_R_joint" type="continuous">
        <parent link="motor_U" />
        <child link="motor_R" />
        <origin rpy="-1.570796325 0 0" xyz="0 0 0.02" />
        <axis xyz="0 0 1" />
        <limit effort="150.0" velocity="3.14159265" />
        <dynamics damping="0.0" friction="0.0" />
    </joint>
    <transmission name="motor_R_joint_trans">
        <type>transmission_interface/SimpleTransmission</type>
        <joint name="motor_R_joint">
            <hardwareInterface>hardware_interface/PositionJointInterface</hardwareInterface>
        </joint>
        <actuator name="motor_R_joint_motor">
            <hardwareInterface>hardware_interface/PositionJointInterface</hardwareInterface>
            <mechanicalReduction>1</mechanicalReduction>
        </actuator>
    </transmission>
    <gazebo reference="motor_R">
        <material>Gazebo/Gray</material>
    </gazebo>
    <link name="pole_2">
        <visual>
            <origin rpy="0 0 0" xyz="0 0 0" />
            <geometry>
                <cylinder length="0.1" radius="0.01" />
            </geometry>
            <material name="white">
                <color rgba="1 1 1 1" />
            </material>
        </visual>
        <collision>
            <geometry>
                <cylinder length="0.1" radius="0.01" />
            </geometry>
        </collision>

        <inertial>
            <origin rpy="0 0 0" xyz="0 0 0" />
            <mass value="5" />
            <inertia ixx="0.00429166495" ixy="0.0" ixz="0.0" iyy="0.00429166495" iyz="0.0" izz="0.00025" />
        </inertial>

    </link>
    <joint name="pole_2_joint" type="fixed">
        <parent link="motor_R" />
        <child link="pole_2" />
        <origin rpy="0 0 0" xyz="0 0 0.06" />
    </joint>
    <gazebo reference="pole_2">
        <material>Gazebo/White</material>
    </gazebo>
    <link name="motor_B">
        <visual>
            <origin rpy="0 0 0" xyz="0 0 0" />
            <geometry>
                <cylinder length="0.02" radius="0.01" />
            </geometry>
            <material name="gray">
                <color rgba="0.75 0.75 0.75 1" />
            </material>
        </visual>
        <collision>
            <geometry>
                <cylinder length="0.02" radius="0.01" />
            </geometry>
        </collision>

        <inertial>
            <origin rpy="0 0 0" xyz="0 0 0" />
            <mass value="1" />
            <inertia ixx="5.833331e-05" ixy="0.0" ixz="0.0" iyy="5.833331e-05" iyz="0.0" izz="5e-05" />
        </inertial>

    </link>
    <joint name="motor_B_joint" type="continuous">
        <parent link="pole_2" />
        <child link="motor_B" />
        <origin rpy="1.570796325 0 0" xyz="0 0 0.06" />
        <axis xyz="0 0 1" />
        <limit effort="150.0" velocity="3.14159265" />
        <dynamics damping="0.0" friction="0.0" />
    </joint>
    <transmission name="motor_B_joint_trans">
        <type>transmission_interface/SimpleTransmission</type>
        <joint name="motor_B_joint">
            <hardwareInterface>hardware_interface/PositionJointInterface</hardwareInterface>
        </joint>
        <actuator name="motor_B_joint_motor">
            <hardwareInterface>hardware_interface/PositionJointInterface</hardwareInterface>
            <mechanicalReduction>1</mechanicalReduction>
        </actuator>
    </transmission>
    <gazebo reference="motor_B">
        <material>Gazebo/Gray</material>
    </gazebo>
    <link name="motor_T">
        <visual>
            <origin rpy="0 0 0" xyz="0 0 0" />
            <geometry>
                <cylinder length="0.02" radius="0.01" />
            </geometry>
            <material name="gray">
                <color rgba="0.75 0.75 0.75 1" />
            </material>
        </visual>
        <collision>
            <geometry>
                <cylinder length="0.02" radius="0.01" />
            </geometry>
        </collision>

        <inertial>
            <origin rpy="0 0 0" xyz="0 0 0" />
            <mass value="1" />
            <inertia ixx="5.833331e-05" ixy="0.0" ixz="0.0" iyy="5.833331e-05" iyz="0.0" izz="5e-05" />
        </inertial>

    </link>
    <joint name="motor_T_joint" type="continuous">
        <parent link="motor_B" />
        <child link="motor_T" />
        <origin rpy="-1.570796325 0 0" xyz="0 0 0.02" />
        <axis xyz="0 0 1" />
        <limit effort="150.0" velocity="3.14159265" />
        <dynamics damping="0.0" friction="0.0" />
    </joint>
    <transmission name="motor_T_joint_trans">
        <type>transmission_interface/SimpleTransmission</type>
        <joint name="motor_T_joint">
            <hardwareInterface>hardware_interface/PositionJointInterface</hardwareInterface>
        </joint>
        <actuator name="motor_T_joint_motor">
            <hardwareInterface>hardware_interface/PositionJointInterface</hardwareInterface>
            <mechanicalReduction>1</mechanicalReduction>
        </actuator>
    </transmission>
    <gazebo reference="motor_T">
        <material>Gazebo/Gray</material>
    </gazebo>
    <link name="wrist_link" />
    <joint name="wrist_joint" type="fixed">
        <parent link="motor_T" />
        <child link="wrist_link" />
        <origin rpy="0 0 0" xyz="0 0 0.01" />
    </joint>
    <transmission name="trans_motor_S_joint">
        <type>transmission_interface/SimpleTransmission</type>
        <joint name="motor_S_joint">
            <hardwareInterface>hardware_interface/PositionJointInterface</hardwareInterface>
        </joint>
        <actuator name="motor_S_joint_motor">
            <hardwareInterface>hardware_interface/PositionJointInterface</hardwareInterface>
            <mechanicalReduction>1</mechanicalReduction>
        </actuator>
    </transmission>
    <transmission name="trans_motor_L_joint">
        <type>transmission_interface/SimpleTransmission</type>
        <joint name="motor_L_joint">
            <hardwareInterface>hardware_interface/PositionJointInterface</hardwareInterface>
        </joint>
        <actuator name="motor_L_joint_motor">
            <hardwareInterface>hardware_interface/PositionJointInterface</hardwareInterface>
            <mechanicalReduction>1</mechanicalReduction>
        </actuator>
    </transmission>
    <transmission name="trans_motor_U_joint">
        <type>transmission_interface/SimpleTransmission</type>
        <joint name="motor_U_joint">
            <hardwareInterface>hardware_interface/PositionJointInterface</hardwareInterface>
        </joint>
        <actuator name="motor_U_joint_motor">
            <hardwareInterface>hardware_interface/PositionJointInterface</hardwareInterface>
            <mechanicalReduction>1</mechanicalReduction>
        </actuator>
    </transmission>
    <transmission name="trans_motor_R_joint">
        <type>transmission_interface/SimpleTransmission</type>
        <joint name="motor_R_joint">
            <hardwareInterface>hardware_interface/PositionJointInterface</hardwareInterface>
        </joint>
        <actuator name="motor_R_joint_motor">
            <hardwareInterface>hardware_interface/PositionJointInterface</hardwareInterface>
            <mechanicalReduction>1</mechanicalReduction>
        </actuator>
    </transmission>
    <transmission name="trans_motor_B_joint">
        <type>transmission_interface/SimpleTransmission</type>
        <joint name="motor_B_joint">
            <hardwareInterface>hardware_interface/PositionJointInterface</hardwareInterface>
        </joint>
        <actuator name="motor_B_joint_motor">
            <hardwareInterface>hardware_interface/PositionJointInterface</hardwareInterface>
            <mechanicalReduction>1</mechanicalReduction>
        </actuator>
    </transmission>
    <transmission name="trans_motor_T_joint">
        <type>transmission_interface/SimpleTransmission</type>
        <joint name="motor_T_joint">
            <hardwareInterface>hardware_interface/PositionJointInterface</hardwareInterface>
        </joint>
        <actuator name="motor_T_joint_motor">
            <hardwareInterface>hardware_interface/PositionJointInterface</hardwareInterface>
            <mechanicalReduction>1</mechanicalReduction>
        </actuator>
    </transmission>
    <gazebo>
        <plugin name="gazebo_ros_control" filename="libgazebo_ros_control.so">
            <robotNamespace>/</robotNamespace>
        </plugin>
    </gazebo>
</robot>